<?xml version="1.0" ?>
<robot name="centaur2" xmlns:xacro="http://www.ros.org/wiki/xacro">

<xacro:include filename="$(find centaur2_description)/urdf/materials.xacro" />
<xacro:include filename="$(find centaur2_description)/urdf/centaur2.trans" />
<xacro:include filename="$(find centaur2_description)/urdf/centaur2.gazebo" />
<link name="base_link">
  <inertial>
    <origin rpy="0 0 0" xyz="-5.0902174876003435e-06 -3.071086506139217e-07 0.061"/>
    <mass value="3.1566880672959843"/>
    <inertia ixx="0.109551" ixy="2e-06" ixz="0.0" iyy="0.033937" iyz="-0.0" izz="0.143485"/>
  </inertial>
  <visual>
    <origin rpy="0 0 0" xyz="0 0 0"/>
    <geometry>
      <mesh filename="package://centaur2_description/meshes/base_link.stl" scale="0.001 0.001 0.001"/>
    </geometry>
    <material name="silver"/>
  </visual>
  <collision>
    <origin rpy="0 0 0" xyz="0 0 0"/>
    <geometry>
      <mesh filename="package://centaur2_description/meshes/base_link.stl" scale="0.001 0.001 0.001"/>
    </geometry>
  </collision>
</link>

<link name="Frame_1">
  <inertial>
    <origin rpy="0 0 0" xyz="-0.17459999999999457 0.15239999999999432 0.24767505978023951"/>
    <mass value="4.323917657600147"/>
    <inertia ixx="0.381877" ixy="0.0" ixz="0.0" iyy="0.249814" iyz="0.0" izz="0.368988"/>
  </inertial>
  <visual>
    <origin rpy="0 0 0" xyz="-0.1746 0.1524 -0.002"/>
    <geometry>
      <mesh filename="package://centaur2_description/meshes/Frame_1.stl" scale="0.001 0.001 0.001"/>
    </geometry>
    <material name="silver"/>
  </visual>
  <collision>
    <origin rpy="0 0 0" xyz="-0.1746 0.1524 -0.002"/>
    <geometry>
      <mesh filename="package://centaur2_description/meshes/Frame_1.stl" scale="0.001 0.001 0.001"/>
    </geometry>
  </collision>
</link>

<link name="wheel_Lock__1___1___1__1">
  <inertial>
    <origin rpy="0 0 0" xyz="2.6047542733831364e-09 -4.341134701713045e-09 -0.0034999999999999892"/>
    <mass value="0.0350291722005078"/>
    <inertia ixx="2e-06" ixy="0.0" ixz="0.0" iyy="2e-06" iyz="0.0" izz="3e-06"/>
  </inertial>
  <visual>
    <origin rpy="0 0 0" xyz="0.15 -0.25 -0.072"/>
    <geometry>
      <mesh filename="package://centaur2_description/meshes/wheel_Lock__1___1___1__1.stl" scale="0.001 0.001 0.001"/>
    </geometry>
    <material name="silver"/>
  </visual>
  <collision>
    <origin rpy="0 0 0" xyz="0.15 -0.25 -0.072"/>
    <geometry>
      <mesh filename="package://centaur2_description/meshes/wheel_Lock__1___1___1__1.stl" scale="0.001 0.001 0.001"/>
    </geometry>
  </collision>
</link>

<link name="wheel_Lock__1___1__1">
  <inertial>
    <origin rpy="0 0 0" xyz="2.604754301138712e-09 -4.341134701713045e-09 -0.0034999999999999892"/>
    <mass value="0.0350291722005078"/>
    <inertia ixx="2e-06" ixy="0.0" ixz="0.0" iyy="2e-06" iyz="0.0" izz="3e-06"/>
  </inertial>
  <visual>
    <origin rpy="0 0 0" xyz="-0.15 -0.25 -0.072"/>
    <geometry>
      <mesh filename="package://centaur2_description/meshes/wheel_Lock__1___1__1.stl" scale="0.001 0.001 0.001"/>
    </geometry>
    <material name="silver"/>
  </visual>
  <collision>
    <origin rpy="0 0 0" xyz="-0.15 -0.25 -0.072"/>
    <geometry>
      <mesh filename="package://centaur2_description/meshes/wheel_Lock__1___1__1.stl" scale="0.001 0.001 0.001"/>
    </geometry>
  </collision>
</link>

<link name="wheel_Lock__1__1">
  <inertial>
    <origin rpy="0 0 0" xyz="2.6047542733831364e-09 -4.341134729468621e-09 -0.0034999999999999892"/>
    <mass value="0.0350291722005078"/>
    <inertia ixx="2e-06" ixy="-0.0" ixz="0.0" iyy="2e-06" iyz="-0.0" izz="3e-06"/>
  </inertial>
  <visual>
    <origin rpy="0 0 0" xyz="0.15 0.25 -0.072"/>
    <geometry>
      <mesh filename="package://centaur2_description/meshes/wheel_Lock__1__1.stl" scale="0.001 0.001 0.001"/>
    </geometry>
    <material name="silver"/>
  </visual>
  <collision>
    <origin rpy="0 0 0" xyz="0.15 0.25 -0.072"/>
    <geometry>
      <mesh filename="package://centaur2_description/meshes/wheel_Lock__1__1.stl" scale="0.001 0.001 0.001"/>
    </geometry>
  </collision>
</link>

<link name="wheel_Lock_1">
  <inertial>
    <origin rpy="0 0 0" xyz="2.604754301138712e-09 -4.341134729468621e-09 -0.0034999999999999892"/>
    <mass value="0.0350291722005078"/>
    <inertia ixx="2e-06" ixy="-0.0" ixz="0.0" iyy="2e-06" iyz="-0.0" izz="3e-06"/>
  </inertial>
  <visual>
    <origin rpy="0 0 0" xyz="-0.15 0.25 -0.072"/>
    <geometry>
      <mesh filename="package://centaur2_description/meshes/wheel_Lock_1.stl" scale="0.001 0.001 0.001"/>
    </geometry>
    <material name="silver"/>
  </visual>
  <collision>
    <origin rpy="0 0 0" xyz="-0.15 0.25 -0.072"/>
    <geometry>
      <mesh filename="package://centaur2_description/meshes/wheel_Lock_1.stl" scale="0.001 0.001 0.001"/>
    </geometry>
  </collision>
</link>

<link name="falseCaster_1">
  <inertial>
    <origin rpy="0 0 0" xyz="-5.551115123125783e-17 5.551115123125783e-17 -0.036944766188335865"/>
    <mass value="0.558921991463318"/>
    <inertia ixx="0.000195" ixy="-0.0" ixz="-0.0" iyy="0.000195" iyz="0.0" izz="0.000113"/>
  </inertial>
  <visual>
    <origin rpy="0 0 0" xyz="0.15 -0.25 -0.07"/>
    <geometry>
      <mesh filename="package://centaur2_description/meshes/falseCaster_1.stl" scale="0.001 0.001 0.001"/>
    </geometry>
    <material name="silver"/>
  </visual>
  <collision>
    <origin rpy="0 0 0" xyz="0.15 -0.25 -0.07"/>
    <geometry>
      <mesh filename="package://centaur2_description/meshes/falseCaster_1.stl" scale="0.001 0.001 0.001"/>
    </geometry>
  </collision>
</link>

<link name="falseCaster__1__1">
  <inertial>
    <origin rpy="0 0 0" xyz="5.551115123125783e-17 0.0 -0.036944766188335885"/>
    <mass value="0.558921991463318"/>
    <inertia ixx="0.000195" ixy="0.0" ixz="0.0" iyy="0.000195" iyz="-0.0" izz="0.000113"/>
  </inertial>
  <visual>
    <origin rpy="0 0 0" xyz="-0.15 -0.25 -0.07"/>
    <geometry>
      <mesh filename="package://centaur2_description/meshes/falseCaster__1__1.stl" scale="0.001 0.001 0.001"/>
    </geometry>
    <material name="silver"/>
  </visual>
  <collision>
    <origin rpy="0 0 0" xyz="-0.15 -0.25 -0.07"/>
    <geometry>
      <mesh filename="package://centaur2_description/meshes/falseCaster__1__1.stl" scale="0.001 0.001 0.001"/>
    </geometry>
  </collision>
</link>

<link name="falseCaster__1___1__1">
  <inertial>
    <origin rpy="0 0 0" xyz="-5.551115123125783e-17 0.0 -0.036944766188335865"/>
    <mass value="0.558921991463318"/>
    <inertia ixx="0.000195" ixy="0.0" ixz="-0.0" iyy="0.000195" iyz="-0.0" izz="0.000113"/>
  </inertial>
  <visual>
    <origin rpy="0 0 0" xyz="0.15 0.25 -0.07"/>
    <geometry>
      <mesh filename="package://centaur2_description/meshes/falseCaster__1___1__1.stl" scale="0.001 0.001 0.001"/>
    </geometry>
    <material name="silver"/>
  </visual>
  <collision>
    <origin rpy="0 0 0" xyz="0.15 0.25 -0.07"/>
    <geometry>
      <mesh filename="package://centaur2_description/meshes/falseCaster__1___1__1.stl" scale="0.001 0.001 0.001"/>
    </geometry>
  </collision>
</link>

<link name="falseCaster__1___1___1__1">
  <inertial>
    <origin rpy="0 0 0" xyz="5.551115123125783e-17 2.7755575615628914e-17 -0.036944766188335885"/>
    <mass value="0.558921991463318"/>
    <inertia ixx="0.000195" ixy="0.0" ixz="0.0" iyy="0.000195" iyz="0.0" izz="0.000113"/>
  </inertial>
  <visual>
    <origin rpy="0 0 0" xyz="-0.15 0.25 -0.07"/>
    <geometry>
      <mesh filename="package://centaur2_description/meshes/falseCaster__1___1___1__1.stl" scale="0.001 0.001 0.001"/>
    </geometry>
    <material name="silver"/>
  </visual>
  <collision>
    <origin rpy="0 0 0" xyz="-0.15 0.25 -0.07"/>
    <geometry>
      <mesh filename="package://centaur2_description/meshes/falseCaster__1___1___1__1.stl" scale="0.001 0.001 0.001"/>
    </geometry>
  </collision>
</link>

<link name="wheelShaft_1">
  <inertial>
    <origin rpy="0 0 0" xyz="0.07802595773901487 -5.542764220350314e-18 -0.18972942904550422"/>
    <mass value="0.8050510906075322"/>
    <inertia ixx="0.000154" ixy="-0.0" ixz="-0.0" iyy="0.006671" iyz="0.0" izz="0.006781"/>
  </inertial>
  <visual>
    <origin rpy="0 0 0" xyz="0.078 -0.0 -0.262"/>
    <geometry>
      <mesh filename="package://centaur2_description/meshes/wheelShaft_1.stl" scale="0.001 0.001 0.001"/>
    </geometry>
    <material name="silver"/>
  </visual>
  <collision>
    <origin rpy="0 0 0" xyz="0.078 -0.0 -0.262"/>
    <geometry>
      <mesh filename="package://centaur2_description/meshes/wheelShaft_1.stl" scale="0.001 0.001 0.001"/>
    </geometry>
  </collision>
</link>

<link name="AERO-FLEX_WHEEL_v1_1">
  <inertial>
    <origin rpy="0 0 0" xyz="0.18838357048487236 -1.9664923038311857e-06 0.06390320249033342"/>
    <mass value="2.253848480624703"/>
    <inertia ixx="0.00732" ixy="0.0" ixz="0.0" iyy="0.003764" iyz="0.0" izz="0.003764"/>
  </inertial>
  <visual>
    <origin rpy="0 0 0" xyz="-0.0 -0.0 -0.009325"/>
    <geometry>
      <mesh filename="package://centaur2_description/meshes/AERO-FLEX_WHEEL_v1_1.stl" scale="0.001 0.001 0.001"/>
    </geometry>
    <material name="silver"/>
  </visual>
  <collision>
    <origin rpy="0 0 0" xyz="-0.0 -0.0 -0.009325"/>
    <geometry>
      <mesh filename="package://centaur2_description/meshes/AERO-FLEX_WHEEL_v1_1.stl" scale="0.001 0.001 0.001"/>
    </geometry>
  </collision>
</link>

<link name="AERO-FLEX_WHEEL_v1__1__1">
  <inertial>
    <origin rpy="0 0 0" xyz="-0.18796642951512765 -1.9664923038311835e-06 0.08255320249033389"/>
    <mass value="2.253848480624703"/>
    <inertia ixx="0.00732" ixy="0.0" ixz="0.0" iyy="0.003764" iyz="0.0" izz="0.003764"/>
  </inertial>
  <visual>
    <origin rpy="0 0 0" xyz="0.0 0.0 0.009325"/>
    <geometry>
      <mesh filename="package://centaur2_description/meshes/AERO-FLEX_WHEEL_v1__1__1.stl" scale="0.001 0.001 0.001"/>
    </geometry>
    <material name="silver"/>
  </visual>
  <collision>
    <origin rpy="0 0 0" xyz="0.0 0.0 0.009325"/>
    <geometry>
      <mesh filename="package://centaur2_description/meshes/AERO-FLEX_WHEEL_v1__1__1.stl" scale="0.001 0.001 0.001"/>
    </geometry>
  </collision>
</link>

<joint name="Rigid2" type="fixed">
  <origin rpy="0 0 0" xyz="0.1746 -0.1524 0.002"/>
  <parent link="base_link"/>
  <child link="Frame_1"/>
</joint>

<joint name="Rigid8" type="fixed">
  <origin rpy="0 0 0" xyz="-0.15 0.25 0.072"/>
  <parent link="base_link"/>
  <child link="wheel_Lock__1___1___1__1"/>
</joint>

<joint name="Rigid9" type="fixed">
  <origin rpy="0 0 0" xyz="0.15 0.25 0.072"/>
  <parent link="base_link"/>
  <child link="wheel_Lock__1___1__1"/>
</joint>

<joint name="Rigid10" type="fixed">
  <origin rpy="0 0 0" xyz="-0.15 -0.25 0.072"/>
  <parent link="base_link"/>
  <child link="wheel_Lock__1__1"/>
</joint>

<joint name="Rigid11" type="fixed">
  <origin rpy="0 0 0" xyz="0.15 -0.25 0.072"/>
  <parent link="base_link"/>
  <child link="wheel_Lock_1"/>
</joint>

<joint name="Rigid15" type="fixed">
  <origin rpy="0 0 0" xyz="-0.15 0.25 0.07"/>
  <parent link="base_link"/>
  <child link="falseCaster_1"/>
</joint>

<joint name="Rigid16" type="fixed">
  <origin rpy="0 0 0" xyz="0.15 0.25 0.07"/>
  <parent link="base_link"/>
  <child link="falseCaster__1__1"/>
</joint>

<joint name="Rigid17" type="fixed">
  <origin rpy="0 0 0" xyz="-0.15 -0.25 0.07"/>
  <parent link="base_link"/>
  <child link="falseCaster__1___1__1"/>
</joint>

<joint name="Rigid18" type="fixed">
  <origin rpy="0 0 0" xyz="0.15 -0.25 0.07"/>
  <parent link="base_link"/>
  <child link="falseCaster__1___1___1__1"/>
</joint>

<joint name="Rigid21" type="fixed">
  <origin rpy="0 0 0" xyz="-0.078 0.0 0.262"/>
  <parent link="base_link"/>
  <child link="wheelShaft_1"/>
</joint>

<joint name="Rev22" type="continuous">
  <origin rpy="0 0 0" xyz="0.078 0.0 -0.252675"/>
  <parent link="wheelShaft_1"/>
  <child link="AERO-FLEX_WHEEL_v1_1"/>
  <axis xyz="1.0 -0.0 0.0"/>
</joint>

<joint name="Rev23" type="continuous">
  <origin rpy="0 0 0" xyz="0.078 -0.0 -0.271325"/>
  <parent link="wheelShaft_1"/>
  <child link="AERO-FLEX_WHEEL_v1__1__1"/>
  <axis xyz="-1.0 -0.0 0.0"/>
</joint>

</robot>
